<mujocoinclude>

  <body name="palm" quat="0 1 0 1" childclass="allegro_left">
    <geom quat="1 -1 0 0" class="palm_visual" mesh="base_link_left"/>
    <!-- <geom quat="1 -1 0 0" mesh="base_link_left"/> -->
    <geom class="palm_collision"/>
    <site name="S_grasp" type="sphere" rgba="0 0 0 0" size="0.01" pos=".007 -.05 0.07" quat="0.0087 -0.6 -0.0034 -0.81" />
    <!-- TODO: check S_grasp i.e. palm position -->
    <!-- Ring finger -->
    <body name="rf_base" pos="0 0.0435 -0.001542" quat="0.999048 -0.0436194 0 0">
      <joint name="rfj0" class="base"/>
      <geom class="base_visual"/>
      <geom class="base_collision"/>
      <body name="rf_proximal" pos="0 0 0.0164">
        <joint name="rfj1" class="proximal"/>
        <geom class="proximal_visual"/>
        <geom class="proximal_collision"/>
        <body name="rf_medial" pos="0 0 0.054">
          <joint name="rfj2" class="medial"/>
          <geom class="medial_visual"/>
          <geom class="medial_collision"/>
          <body name="rf_distal" pos="0 0 0.0384">
            <joint name="rfj3" class="distal"/>
            <geom class="distal_visual"/>
            <geom class="distal_collision"/>
            <body name="rf_tip">
              <geom class="fingertip_visual"/>
              <geom class="fingertip_collision"/>
            </body>
          </body>
        </body>
      </body>
    </body>
    <!-- Middle finger -->
    <body name="mf_base" pos="0 0 0.0007">
      <joint name="mfj0" class="base"/>
      <geom class="base_visual"/>
      <geom class="base_collision"/>
      <body name="mf_proximal" pos="0 0 0.0164">
        <joint name="mfj1" class="proximal"/>
        <geom class="proximal_visual"/>
        <geom class="proximal_collision"/>
        <body name="mf_medial" pos="0 0 0.054">
          <joint name="mfj2" class="medial"/>
          <geom class="medial_visual"/>
          <geom class="medial_collision"/>
          <body name="mf_distal" pos="0 0 0.0384">
            <joint name="mfj3" class="distal"/>
            <geom class="distal_visual"/>
            <geom class="distal_collision"/>
            <body name="mf_tip">
              <geom class="fingertip_visual"/>
              <geom class="fingertip_collision"/>
            </body>
          </body>
        </body>
      </body>
    </body>
    <!-- First finger -->
    <body name="ff_base" pos="0 -0.0435 -0.001542" quat="0.999048 0.0436194 0 0">
      <joint name="ffj0" class="base"/>
      <geom class="base_visual"/>
      <geom class="base_collision"/>
      <body name="ff_proximal" pos="0 0 0.0164">
        <joint name="ffj1" class="proximal"/>
        <geom class="proximal_visual"/>
        <!-- <geom class="visual" mesh="link_1.0"/> -->
        <geom class="proximal_collision"/>
        <body name="ff_medial" pos="0 0 0.054">
          <joint name="ffj2" class="medial"/>
          <geom class="medial_visual"/>
          <!-- <geom class="visual" mesh="link_2.0"/> -->
          <geom class="medial_collision"/>
          <body name="ff_distal" pos="0 0 0.0384">
            <joint name="ffj3" class="distal"/>
            <geom class="distal_visual"/>
            <!-- <geom class="visual" mesh="link_3.0"/> -->
            <geom class="distal_collision"/>
            <body name="ff_tip">
              <geom class="fingertip_visual"/>
              <geom class="fingertip_collision"/>
            </body>
          </body>
        </body>
      </body>
    </body>
    <!-- Thumb -->
    <body name="th_base" pos="-0.0182 -0.019333 -0.045987" quat="0.477714 0.521334 -0.521334 0.477714">
      <joint name="thj0" class="thumb_base"/>
      <geom quat="0 1 0 0" class="visual" mesh="link_12.0_left"/>
      <geom class="thumb_base_collision"/>
      <body name="th_proximal" pos="-0.027 -0.005 0.0399">
        <joint name="thj1" class="thumb_proximal"/>
        <geom class="visual" mesh="link_13.0"/>
        <geom class="thumb_proximal_collision"/>
        <body name="th_medial" pos="0 0 0.0177">
          <joint name="thj2" class="thumb_medial"/>
          <geom class="visual" mesh="link_14.0"/>
          <geom class="thumb_medial_collision"/>
          <body name="th_distal" pos="0 0 0.0514">
            <joint name="thj3" class="thumb_distal"/>
            <geom class="visual" mesh="link_15.0"/>
            <geom class="thumb_distal_collision"/>
            <body name="th_tip">
              <geom class="thumbtip_visual"/>
              <geom class="thumbtip_collision"/>
            </body>
          </body>
        </body>
      </body>
    </body>
  </body>

</mujocoinclude>
